Workbook

Sheet REALISASI SMB 2026
A1: CAPAIAN REALISASI PENERIMAAN
A2: BERDASARKAN SUMBER DANA
A3: Periode : 1 JANUARI 2026 sd 09 Juli 2026
A4: TAHUN ANGGARAN 2026
A6: NO | B6: KETERANGAN SUMBER DANA | C6: REALISASI PENERIMAAN
A9: 1 | B9: DAK | C9: =SUMIF('Data Input'!$J$8:$J$10020,'REALISASI SMB 2026'!B9,'Data Input'!$H$8:$H$10020) -> 1394341140
A10: 2 | B10: Dana Transfer Umum-Dana Alokasi Umum | C10: =SUMIF('Data Input'!$J$8:$J$10020,'REALISASI SMB 2026'!B10,'Data Input'!$H$8:$H$10020) -> 733480937000
A11: 3 | B11: Dana Transfer Umum-Dana Bagi Hasil | C11: =SUMIF('Data Input'!$J$8:$J$10020,'REALISASI SMB 2026'!B11,'Data Input'!$H$8:$H$10020) -> 106068600800
A12: 4 | B12: DAU yang Ditentukan Penggunaannya Bidang Kesehatan | C12: =SUMIF('Data Input'!$J$8:$J$10020,'REALISASI SMB 2026'!B12,'Data Input'!$H$8:$H$10020) -> 0
A13: 5 | B13: DAU yang Ditentukan Penggunaannya Bidang Pendidikan | C13: =SUMIF('Data Input'!$J$8:$J$10020,'REALISASI SMB 2026'!B13,'Data Input'!$H$8:$H$10020) -> 0
A14: 6 | B14: DBH Cukai Hasil Tembakau (CHT) | C14: =SUMIF('Data Input'!$J$8:$J$10020,'REALISASI SMB 2026'!B14,'Data Input'!$H$8:$H$10020) -> 0
A15: 7 | B15: DBH Sawit | C15: =SUMIF('Data Input'!$J$8:$J$10020,'REALISASI SMB 2026'!B15,'Data Input'!$H$8:$H$10020) -> 723194000
A16: 8 | B16: DBH Sumber Daya Alam Kehutanan-Dana Reboisasi (DR) | C16: =SUMIF('Data Input'!$J$8:$J$10020,'REALISASI SMB 2026'!B16,'Data Input'!$H$8:$H$10020) -> 1557999600
A17: 9 | B17: Hibah | C17: =SUMIF('Data Input'!$J$8:$J$10020,'REALISASI SMB 2026'!B17,'Data Input'!$H$8:$H$10020) -> 537174283
A18: 10 | B18: Pajak Kendaraan Bermotor (PKB) | C18: =SUMIF('Data Input'!$J$8:$J$10020,'REALISASI SMB 2026'!B18,'Data Input'!$H$8:$H$10020) -> 108432807666
A19: 11 | B19: Pajak Rokok | C19: =SUMIF('Data Input'!$J$8:$J$10020,'REALISASI SMB 2026'!B19,'Data Input'!$H$8:$H$10020) -> 79272454607
A20: 12 | B20: PENDAPATAN ASLI DAERAH (PAD) | C20: =SUMIF('Data Input'!$J$8:$J$10020,'REALISASI SMB 2026'!B20,'Data Input'!$H$8:$H$10020) -> 7.738187e+11
... A22: 14 | B22: Pengembalian Belanja 2026 | C22: =SUMIF('Data Input'!$J$8:$J$10020,'REALISASI SMB 2026'!B22,'Data Input'!$H$8:$H$10020) -> 714971124
B23: JUMLAH | C23: =SUM(C9:C22) -> 1.8685036e+12

Sheet Data Input
B2: REKAPITULASI PENERIMAAN BULAN JANUARI 2026
B4: NO | C4: RC | D4: TANGGAL | F4: NO. BKU | G4: AYAT PENERIMAAN | H4: JUMLAH STS | I4: JUMLAH / TANGGAL | J4: SUMBER DANA
D5: RC | E5: BKU
B6: 1 | C6: 2 | D6: 3 | E6: 4 | F6: 5 | G6: 6 | H6: 7 | I6: 8 | J6: 9
G8: SALDO AWAL 2026 | H8: 6.2502377e+10 | I8: 6.2502377e+10 | J8: SILPA
B9: 1 | C9: 14-4 | D9: 46024 | E9: 46024 | F9: 1 | G9: TRF_INT Sikap_Pengembalian Jasa Giro Desember 2025 BPP Dinas ESDM | H9: 28178 | J9: PENDAPATAN ASLI DAERAH (PAD)
B10: 2 | C10: 14-4 | D10: 46024 | E10: 46024 | F10: 2 | G10: DAU, Bulan Januari Tahun 2026 Yang Tidak Ditentukan Penggunaannya | H10: 104782991000 | J10: Dana Transfer Umum-Dana Alokasi Umum
B11: 3 | C11: 26-7 | D11: 46024 | E11: 46024 | F11: 3 | G11: ATM_Elsa Trirahmani_Disbunnak Sewa Uji Lab | H11: 20900000 | J11: PENDAPATAN ASLI DAERAH (PAD)
B12: 4 | C12: 26-7 | D12: 46024 | E12: 46024 | F12: 4 | G12: Tunai Disdik Pengembalian Biaya Asuransi PKL SMKN 1 Batui Selatan TA 2025 | H12: 873600 | J12: PENDAPATAN ASLI DAERAH (PAD)
B13: 5 | C13: 26-7 | D13: 46024 | E13: 46024 | F13: 5 | G13: Dinas Cikasda II Sewa Kantin Desember 2025 | H13: 250000 | J13: PENDAPATAN ASLI DAERAH (PAD)
B14: 6 | C14: 26-7 | D14: 46024 | E14: 46024 | F14: 6 | G14: Dinas Cikasda Sewa Kantin Desember 2025 | H14: 250000 | J14: PENDAPATAN ASLI DAERAH (PAD)
B15: 7 | C15: 26-7 | D15: 46024 | E15: 46024 | F15: 7 | G15: Dinas Cikasda Sewa Rumdis Januari An. Jhony Kandow 2026 | H15: 280000 | J15: PENDAPATAN ASLI DAERAH (PAD)
B16: 8 | C16: 26-7 | D16: 46024 | E16: 46024 | F16: 8 | G16: Disnakertrans Sewa BMD Rumdis An. Suryani Yusuf Desember Tahun 2025 | H16: 320000 | J16: PENDAPATAN ASLI DAERAH (PAD)
B17: 9 | C17: 26-7 | D17: 46024 | E17: 46024 | F17: 9 | G17: Pelkes Labkes | H17: 6962000 | J17: PENDAPATAN ASLI DAERAH (PAD)
B18: 10 | C18: 26-7 | D18: 46024 | E18: 46024 | F18: 10 | G18: ATM_PT Tri Multi Daya_PBBKB | H18: 34927220 | J18: PENDAPATAN ASLI DAERAH (PAD)
B19: 11 | C19: 26-7 | D19: 46024 | E19: 46024 | F19: 11 | G19: Dikbud UPT Museum Sewa Gedung (Karcis) (Qris) | H19: 30000 | J19: PENDAPATAN ASLI DAERAH (PAD)
B20: 12 | C20: 12-1 | D20: 46024 | E20: 46024 | F20: 12 | G20: PKB | H20: 332974478 | J20: Pajak Kendaraan Bermotor (PKB)
... B23: 15 | C23: 60-0 | D23: 46024 | E23: 46024 | F23: 15 | G23: PKB | H23: 29594047 | J23: Pajak Kendaraan Bermotor (PKB)
B24: 16 | C24: 60-0 | D24: 46024 | E24: 46024 | F24: 16 | G24: Denda PKB | H24: 126830 | I24: =SUM(H9:H24) -> 105218316452 | J24: PENDAPATAN ASLI DAERAH (PAD)
B25: 17 | C25: 26-7 | D25: 46026 | E25: 46027 | F25: 17 | G25: ATM_Ananda Firman_PBBKB | H25: 32088623 | J25: PENDAPATAN ASLI DAERAH (PAD)
B26: 18 | C26: 12-1 | D26: 46025 | E26: 46027 | F26: 18 | G26: PKB | H26: 150894704 | J26: Pajak Kendaraan Bermotor (PKB)
B27: 19 | C27: 12-1 | D27: 46025 | E27: 46027 | F27: 19 | G27: BBNKB | H27: 11424000 | J27: PENDAPATAN ASLI DAERAH (PAD)
B28: 20 | C28: 12-1 | D28: 46025 | E28: 46027 | F28: 20 | G28: Denda PKB | H28: 2132854 | J28: PENDAPATAN ASLI DAERAH (PAD)
B29: 21 | C29: 60-0 | D29: 46025 | E29: 46027 | F29: 21 | G29: PKB | H29: 19953037 | J29: Pajak Kendaraan Bermotor (PKB)
B30: 22 | C30: 60-0 | D30: 46025 | E30: 46027 | F30: 22 | G30: Denda PKB | H30: 177625 | J30: PENDAPATAN ASLI DAERAH (PAD)
B31: 23 | C31: 14-4 | D31: 46027 | E31: 46027 | F31: 23 | G31: Jasa Giro Agustus 2025 BPP Bid. KPP Dispang | H31: 1888 | J31: PENDAPATAN ASLI DAERAH (PAD)
B32: 24 | C32: 14-4 | D32: 46027 | E32: 46027 | F32: 24 | G32: Jasa Giro Agustus sd Desember 2025 BPP Bid. DCPM Dispang | H32: 4424 | J32: PENDAPATAN ASLI DAERAH (PAD)
B33: 25 | C33: 26-7 | D33: 46027 | E33: 46027 | F33: 25 | G33: Tunai Disdik An. Musnaeni Budu Pengembalian Uang Akomodasi / Kontrakan Dana PKL SMKN 1 Petasia TA 2025 | H33: 91100000 | J33: PENDAPATAN ASLI DAERAH (PAD)
B34: 26 | C34: 26-7 | D34: 46027 | E34: 46027 | F34: 26 | G34: Tunai Disdik Set Pengembalian By Seragam, APD, dan Makan Minum/Catering Dana PKL SMKN 1 Petasia Ta.2025 | H34: 2268.81 | J34: PENDAPATAN ASLI DAERAH (PAD)
B35: 27 | C35: 26-7 | D35: 46027 | E35: 46027 | F35: 27 | G35: ATM_Titi Sulpiani_Disdik Cabdis Wil III Pengembalian Tunjangan Fungsional Agustus sd November An. Mohammad A Yusuf TA 2025 | H35: 1556000 | J35: PENDAPATAN ASLI DAERAH (PAD)
B36: 28 | C36: 26-7 | D36: 46027 | E36: 46027 | F36: 28 | G36: Disbunnak Sewa Uji Lab | H36: 4415000 | J36: PENDAPATAN ASLI DAERAH (PAD)
... B64: 56 | C64: 12-1 | D64: 46027 | E64: 46027 | F64: 56 | G64: PAP | H64: 142722846 | J64: PENDAPATAN ASLI DAERAH (PAD)
B65: 57 | C65: 12-1 | D65: 46027 | E65: 46027 | F65: 57A | G65: Pajak Alat Berat | H65: 123586400 | J65: PENDAPATAN ASLI DAERAH (PAD)
C66: 12-1 | D66: 46027 | E66: 46027 | F66: 57B | G66: Denda Pajak Alat Berat | H66: 614500 | J66: PENDAPATAN ASLI DAERAH (PAD)
B67: 58 | C67: 12-1 | D67: 46027 | E67: 46027 | F67: 58 | G67: Denda PKB | H67: 13906161 | J67: PENDAPATAN ASLI DAERAH (PAD)
B68: 59 | C68: 12-1 | D68: 46027 | E68: 46027 | F68: 59 | G68: Denda BBNKB | H68: 880992 | J68: PENDAPATAN ASLI DAERAH (PAD)
B69: 60 | C69: 29-9 | D69: 46027 | E69: 46027 | F69: 60 | G69: Opsen Pajak MBLB | H69: 920475 | J69: PENDAPATAN ASLI DAERAH (PAD)
B70: 61 | C70: 60-0 | D70: 46027 | E70: 46027 | F70: 61 | G70: PKB | H70: 67047035 | J70: Pajak Kendaraan Bermotor (PKB)
B71: 62 | C71: 60-0 | D71: 46027 | E71: 46027 | F71: 62 | G71: Denda PKB | H71: 1987784 | I71: =SUM(H25:H71) -> 1.6020044e+09 | J71: PENDAPATAN ASLI DAERAH (PAD)
B72: 63 | C72: 26-7 | D72: 46028 | E72: 46028 | F72: 63 | G72: Tunai Dinas Perkimtan Kekurangan Volume Pekerjaan Jalan Lingkungan Kel. Birobuli Selatan Kec. Palu Selatan Oleh CV. Ammarco TA 2024 (Temuan BPK) | H72: 78460848 | J72: PENDAPATAN ASLI DAERAH (PAD)
...
